Workbook

Sheet Summary
B2: AY26-27 Classera Plans | Events Tracker
B3: Live summary from the Events sheet. Every number below is a formula, so it updates as you edit the tracker.
B4: Today | C4: =TODAY() -> 46296
B6: Program | C6: Events | D6: Upcoming | E6: Next 14 days | F6: Date TBC | G6: Links Published | H6: Links Missing | I6: Delivered | J6: Registrations | K6: Attendees | L6: Attendance Rate | M6: Avg Satisfaction | N6: Open Flags
B7: Professional Development | C7: =COUNTIFS(Events!$B$2:$B$400,$B7) -> 13 | D7: =COUNTIFS(Events!$B$2:$B$400,$B7,Events!$AE$2:$AE$400,"<>Past",Events!$A$2:$A$400,"<>") -> 10 | E7: =COUNTIFS(Events!$B$2:$B$400,$B7,Events!$AE$2:$AE$400,"Next 14 days") -> 1 | F7: =COUNTIFS(Events!$B$2:$B$400,$B7,Events!$I$2:$I$400,"<>Confirmed",Events!$A$2:$A$400,"<>") -> 0 | G7: =COUNTIFS(Events!$B$2:$B$400,$B7,Events!$T$2:$T$400,"Published") -> 3 | H7: =COUNTIFS(Events!$B$2:$B$400,$B7,Events!$T$2:$T$400,"Missing",Events!$A$2:$A$400,"<>") -> 10 | I7: =COUNTIFS(Events!$B$2:$B$400,$B7,Events!$U$2:$U$400,"Delivered") -> 3 | J7: =SUMIFS(Events!$X$2:$X$400,Events!$B$2:$B$400,$B7) -> 0 | K7: =SUMIFS(Events!$Y$2:$Y$400,Events!$B$2:$B$400,$B7) -> 0 | L7: =IF(J7>0,K7/J7,"-") -> - | M7: =IFERROR(AVERAGEIFS(Events!$AA$2:$AA$400,Events!$AA$2:$AA$400,">0",Events!$B$2:$B$400,$B7),"-") -> - | N7: =COUNTIFS(Events!$B$2:$B$400,$B7,Events!$AG$2:$AG$400,"?*") -> 1
B8: Accreditation | C8: =COUNTIFS(Events!$B$2:$B$400,$B8) -> 19 | D8: =COUNTIFS(Events!$B$2:$B$400,$B8,Events!$AE$2:$AE$400,"<>Past",Events!$A$2:$A$400,"<>") -> 18 | E8: =COUNTIFS(Events!$B$2:$B$400,$B8,Events!$AE$2:$AE$400,"Next 14 days") -> 1 | F8: =COUNTIFS(Events!$B$2:$B$400,$B8,Events!$I$2:$I$400,"<>Confirmed",Events!$A$2:$A$400,"<>") -> 0 | G8: =COUNTIFS(Events!$B$2:$B$400,$B8,Events!$T$2:$T$400,"Published") -> 19 | H8: =COUNTIFS(Events!$B$2:$B$400,$B8,Events!$T$2:$T$400,"Missing",Events!$A$2:$A$400,"<>") -> 0 | I8: =COUNTIFS(Events!$B$2:$B$400,$B8,Events!$U$2:$U$400,"Delivered") -> 0 | J8: =SUMIFS(Events!$X$2:$X$400,Events!$B$2:$B$400,$B8) -> 0 | K8: =SUMIFS(Events!$Y$2:$Y$400,Events!$B$2:$B$400,$B8) -> 0 | L8: =IF(J8>0,K8/J8,"-") -> - | M8: =IFERROR(AVERAGEIFS(Events!$AA$2:$AA$400,Events!$AA$2:$AA$400,">0",Events!$B$2:$B$400,$B8),"-") -> - | N8: =COUNTIFS(Events!$B$2:$B$400,$B8,Events!$AG$2:$AG$400,"?*") -> 2
B9: Enrichment Academy | C9: =COUNTIFS(Events!$B$2:$B$400,$B9) -> 32 | D9: =COUNTIFS(Events!$B$2:$B$400,$B9,Events!$AE$2:$AE$400,"<>Past",Events!$A$2:$A$400,"<>") -> 31 | E9: =COUNTIFS(Events!$B$2:$B$400,$B9,Events!$AE$2:$AE$400,"Next 14 days") -> 3 | F9: =COUNTIFS(Events!$B$2:$B$400,$B9,Events!$I$2:$I$400,"<>Confirmed",Events!$A$2:$A$400,"<>") -> 0 | G9: =COUNTIFS(Events!$B$2:$B$400,$B9,Events!$T$2:$T$400,"Published") -> 11 | H9: =COUNTIFS(Events!$B$2:$B$400,$B9,Events!$T$2:$T$400,"Missing",Events!$A$2:$A$400,"<>") -> 21 | I9: =COUNTIFS(Events!$B$2:$B$400,$B9,Events!$U$2:$U$400,"Delivered") -> 0 | J9: =SUMIFS(Events!$X$2:$X$400,Events!$B$2:$B$400,$B9) -> 0 | K9: =SUMIFS(Events!$Y$2:$Y$400,Events!$B$2:$B$400,$B9) -> 0 | L9: =IF(J9>0,K9/J9,"-") -> - | M9: =IFERROR(AVERAGEIFS(Events!$AA$2:$AA$400,Events!$AA$2:$AA$400,">0",Events!$B$2:$B$400,$B9),"-") -> - | N9: =COUNTIFS(Events!$B$2:$B$400,$B9,Events!$AG$2:$AG$400,"?*") -> 4
B10: Product Events | C10: =COUNTIFS(Events!$B$2:$B$400,$B10) -> 4 | D10: =COUNTIFS(Events!$B$2:$B$400,$B10,Events!$AE$2:$AE$400,"<>Past",Events!$A$2:$A$400,"<>") -> 4 | E10: =COUNTIFS(Events!$B$2:$B$400,$B10,Events!$AE$2:$AE$400,"Next 14 days") -> 0 | F10: =COUNTIFS(Events!$B$2:$B$400,$B10,Events!$I$2:$I$400,"<>Confirmed",Events!$A$2:$A$400,"<>") -> 1 | G10: =COUNTIFS(Events!$B$2:$B$400,$B10,Events!$T$2:$T$400,"Published") -> 0 | H10: =COUNTIFS(Events!$B$2:$B$400,$B10,Events!$T$2:$T$400,"Missing",Events!$A$2:$A$400,"<>") -> 4 | I10: =COUNTIFS(Events!$B$2:$B$400,$B10,Events!$U$2:$U$400,"Delivered") -> 0 | J10: =SUMIFS(Events!$X$2:$X$400,Events!$B$2:$B$400,$B10) -> 0 | K10: =SUMIFS(Events!$Y$2:$Y$400,Events!$B$2:$B$400,$B10) -> 0 | L10: =IF(J10>0,K10/J10,"-") -> - | M10: =IFERROR(AVERAGEIFS(Events!$AA$2:$AA$400,Events!$AA$2:$AA$400,">0",Events!$B$2:$B$400,$B10),"-") -> - | N10: =COUNTIFS(Events!$B$2:$B$400,$B10,Events!$AG$2:$AG$400,"?*") -> 0
B11: In-Person Events | C11: =COUNTIFS(Events!$B$2:$B$400,$B11) -> 12 | D11: =COUNTIFS(Events!$B$2:$B$400,$B11,Events!$AE$2:$AE$400,"<>Past",Events!$A$2:$A$400,"<>") -> 12 | E11: =COUNTIFS(Events!$B$2:$B$400,$B11,Events!$AE$2:$AE$400,"Next 14 days") -> 0 | F11: =COUNTIFS(Events!$B$2:$B$400,$B11,Events!$I$2:$I$400,"<>Confirmed",Events!$A$2:$A$400,"<>") -> 11 | G11: =COUNTIFS(Events!$B$2:$B$400,$B11,Events!$T$2:$T$400,"Published") -> 0 | H11: =COUNTIFS(Events!$B$2:$B$400,$B11,Events!$T$2:$T$400,"Missing",Events!$A$2:$A$400,"<>") -> 12 | I11: =COUNTIFS(Events!$B$2:$B$400,$B11,Events!$U$2:$U$400,"Delivered") -> 0 | J11: =SUMIFS(Events!$X$2:$X$400,Events!$B$2:$B$400,$B11) -> 0 | K11: =SUMIFS(Events!$Y$2:$Y$400,Events!$B$2:$B$400,$B11) -> 0 | L11: =IF(J11>0,K11/J11,"-") -> - | M11: =IFERROR(AVERAGEIFS(Events!$AA$2:$AA$400,Events!$AA$2:$AA$400,">0",Events!$B$2:$B$400,$B11),"-") -> - | N11: =COUNTIFS(Events!$B$2:$B$400,$B11,Events!$AG$2:$AG$400,"?*") -> 0
B12: Total | C12: =COUNTA(Events!$A$2:$A$400) -> 80 | D12: =COUNTIFS(Events!$A$2:$A$400,"<>",Events!$AE$2:$AE$400,"<>Past",Events!$A$2:$A$400,"<>") -> 75 | E12: =COUNTIFS(Events!$A$2:$A$400,"<>",Events!$AE$2:$AE$400,"Next 14 days") -> 5 | F12: =COUNTIFS(Events!$A$2:$A$400,"<>",Events!$I$2:$I$400,"<>Confirmed",Events!$A$2:$A$400,"<>") -> 12 | G12: =COUNTIFS(Events!$A$2:$A$400,"<>",Events!$T$2:$T$400,"Published") -> 33 | H12: =COUNTIFS(Events!$A$2:$A$400,"<>",Events!$T$2:$T$400,"Missing",Events!$A$2:$A$400,"<>") -> 47 | I12: =COUNTIFS(Events!$A$2:$A$400,"<>",Events!$U$2:$U$400,"Delivered") -> 3 | J12: =SUM(Events!$X$2:$X$400) -> 0 | K12: =SUM(Events!$Y$2:$Y$400) -> 0 | L12: =IF(J12>0,K12/J12,"-") -> - | M12: =IFERROR(AVERAGEIFS(Events!$AA$2:$AA$400,Events!$AA$2:$AA$400,">0"),"-") -> - | N12: =COUNTIFS(Events!$A$2:$A$400,"<>",Events!$AG$2:$AG$400,"?*") -> 7
B14: Status pipeline
C15: Planned | D15: Confirmed | E15: Registration Open | F15: Delivered | G15: Postponed | H15: Cancelled
B16: Events | C16: =COUNTIFS(Events!$U$2:$U$400,C$15) -> 37 | D16: =COUNTIFS(Events!$U$2:$U$400,D$15) -> 10 | E16: =COUNTIFS(Events!$U$2:$U$400,E$15) -> 30 | F16: =COUNTIFS(Events!$U$2:$U$400,F$15) -> 3 | G16: =COUNTIFS(Events!$U$2:$U$400,G$15) -> 0 | H16: =COUNTIFS(Events!$U$2:$U$400,H$15) -> 0
B19: Follow-up flags
B20: Update status | C20: =COUNTIFS(Events!$AG$2:$AG$400,B20) -> 2 | D20: Event date has passed but Event Status is not Delivered, Postponed or Cancelled
B21: Add link | C21: =COUNTIFS(Events!$AG$2:$AG$400,B21) -> 1 | D21: Event starts within 14 days (or is running) and has no registration link
B22: Announce | C22: =COUNTIFS(Events!$AG$2:$AG$400,B22) -> 4 | D22: Event starts within 14 days and the announcement is not Published yet

Sheet Guide
B2: How to use this tracker
B4: Source | C4: All 80 events were pulled from plans.classera.com on 1 Oct 2026 (PD plan, Accreditation calendar, Enrichment plan, Product Events, In-Person Events, Full Calendar).
B5: Column colors | C5: Navy headers = plan data from the site. Gold headers (light-yellow cells) = your tracking inputs. Grey headers = formulas, do not type over them.
B6: Daily follow-up | C6: Filter the Events sheet on Action Flag, or check the Follow-up flags block on the Summary sheet.
B7: Event Status | C7: Planned > Confirmed > Registration Open > Delivered. Use Postponed or Cancelled when needed. Past events stay flagged until you set a final status.
B8: Date Status | C8: "Day TBC" rows use the 1st of the month as Start Date and the month end as End Date until the day is confirmed. Update both dates and set Date Status to Confirmed.
B9: Registration Link | C9: Paste the course or short link. Link Status turns Published automatically. Keep it in sync with links.json on the plans site.
B10: Adding events | C10: Type in the first empty row under the table: it extends automatically and the formulas fill down. Use a new Event ID with the program prefix (PD-, ACC-, ENR-, PRD-, INP-).
B11: Dropdown options | C11: Edit the Lists sheet to change the options for Program, Event Status, Announcement Status, Date Status, Delivery Mode and Pricing.
B12: Dashboard | C12: Open the AY26-27 Events Dashboard and drop this file on it (or click Load tracker). It reads the Events sheet by column name, so keep the header names unchanged. Save a new version number each time (v2, v3...).
B13: Example row | C13: PD-S01 shows a complete row: confirmed date, published link and Registration Open status. Fill Owner, Registrations, Attendees and Satisfaction % after delivery.

Sheet Events
A1: Event ID | B1: Program | C1: Track | D1: Event Title (EN) | E1: Event Title (AR) | F1: Partner / Host | G1: Start Date | H1: End Date | I1: Date Status | J1: Month | K1: Semester | L1: Day | M1: Time (KSA) | N1: Audience | O1: Language | P1: Country / Location | Q1: Delivery Mode | R1: Pricing | S1: Registration Link | T1: Link Status | U1: Event Status | V1: Announcement Status | W1: Owner | X1: Registrations | Y1: Attendees | Z1: Attendance Rate | AA1: Satisfaction % | AB1: Next Action | AC1: Due Date | AD1: Notes | AE1: Timing | AF1: Days to Go | AG1: Action Flag
A2: PD-LW1 | B2: Professional Development | C2: Launch Webinar | D2: Launch Webinar 1: Creativity & Accreditation Plan | E2: الويبينار التعريفي الأول: الإبداع وخطة الاعتماد | F2: PS Training Unit | G2: 46293 | H2: 46293 | I2: Confirmed | J2: =IF(G2="","",DATE(YEAR(G2),MONTH(G2),1)) -> 46266 | K2: =IF(G2="","",IF(G2<DATE(2027,2,1),"Semester 1","Semester 2")) -> Semester 1 | L2: =IF(I2="Confirmed",TEXT(G2,"ddd"),"TBC") -> Mon | M2: 5:00 PM | N2: Teachers + School Leaders | P2: Online - Classera Innovation Platform | Q2: Online | S2: https://sh.classera.com/EPD | T2: =IF(TRIM(S2)="","Missing","Published") -> Published | U2: Delivered | V2: Published | W2: Serag | Z2: =IF(N(X2)>0,N(Y2)/X2,"") | AE2: =IF(G2="","",IF(H2<TODAY(),"Past",IF(G2<=TODAY(),"In progress",IF(G2-TODAY()<=14,"Next 14 days",IF(G2-TODAY()<=45,"Next 45 days","Later"))))) -> Past | AF2: =IF(G2="","",IF(H2<TODAY(),"",G2-TODAY())) | AG2: =IF(AND(AE2="Past",U2<>"Delivered",U2<>"Cancelled",U2<>"Postponed"),"Update status",IF(AND(T2="Missing",OR(AE2="In progress",AE2="Next 14 days")),"Add link",IF(AND(AE2="Next 14 days",V2<>"Published"),"Announce","")))
A3: PD-LW2 | B3: Professional Development | C3: Launch Webinar | D3: Launch Webinar 2: Enrichment Programs Plan | E3: الويبينار التعريفي الثاني: خطة البرامج الإثرائية | F3: PS Training Unit | G3: 46294 | H3: 46294 | I3: Confirmed | J3: =IF(G3="","",DATE(YEAR(G3),MONTH(G3),1)) -> 46266 | K3: =IF(G3="","",IF(G3<DATE(2027,2,1),"Semester 1","Semester 2")) -> Semester 1 | L3: =IF(I3="Confirmed",TEXT(G3,"ddd"),"TBC") -> Tue | M3: 10:00 AM | N3: Teachers + School Leaders | P3: Online - Classera Innovation Platform | Q3: Online | S3: https://sh.classera.com/Enrich | T3: =IF(TRIM(S3)="","Missing","Published") -> Published | U3: Delivered | V3: Published | W3: Serag | Z3: =IF(N(X3)>0,N(Y3)/X3,"") | AE3: =IF(G3="","",IF(H3<TODAY(),"Past",IF(G3<=TODAY(),"In progress",IF(G3-TODAY()<=14,"Next 14 days",IF(G3-TODAY()<=45,"Next 45 days","Later"))))) -> Past | AF3: =IF(G3="","",IF(H3<TODAY(),"",G3-TODAY())) | AG3: =IF(AND(AE3="Past",U3<>"Delivered",U3<>"Cancelled",U3<>"Postponed"),"Update status",IF(AND(T3="Missing",OR(AE3="In progress",AE3="Next 14 days")),"Add link",IF(AND(AE3="Next 14 days",V3<>"Published"),"Announce","")))
A4: PD-S01 | B4: Professional Development | C4: Classera LMS | D4: Academic Year Kickoff & Classera LMS Updates: New Features & Release Highlights | E4: انطلاقة العام الأكاديمي وتحديثات نظام كلاسيرا: المزايا الجديدة وأبرز الإصدارات | F4: Classera | G4: 46295 | H4: 46295 | I4: Confirmed | J4: =IF(G4="","",DATE(YEAR(G4),MONTH(G4),1)) -> 46266 | K4: =IF(G4="","",IF(G4<DATE(2027,2,1),"Semester 1","Semester 2")) -> Semester 1 | L4: =IF(I4="Confirmed",TEXT(G4,"ddd"),"TBC") -> Wed | M4: 5:00 PM | N4: All LMS Users | P4: Online - Classera Innovation Platform | Q4: Online | S4: https://sh.classera.com/v17unlocked | T4: =IF(TRIM(S4)="","Missing","Published") -> Published | U4: Delivered | V4: Published | W4: Serag | Z4: =IF(N(X4)>0,N(Y4)/X4,"") | AE4: =IF(G4="","",IF(H4<TODAY(),"Past",IF(G4<=TODAY(),"In progress",IF(G4-TODAY()<=14,"Next 14 days",IF(G4-TODAY()<=45,"Next 45 days","Later"))))) -> Past | AF4: =IF(G4="","",IF(H4<TODAY(),"",G4-TODAY())) | AG4: =IF(AND(AE4="Past",U4<>"Delivered",U4<>"Cancelled",U4<>"Postponed"),"Update status",IF(AND(T4="Missing",OR(AE4="In progress",AE4="Next 14 days")),"Add link",IF(AND(AE4="Next 14 days",V4<>"Published"),"Announce","")))
A5: PD-S02 | B5: Professional Development | C5: Intel SFI | D5: Intel Skills for Innovation (SFI) Webinar 1: AI Professional Development | E5: Intel Skills for Innovation: التطوير المهني في الذكاء الاصطناعي (1) | F5: Intel | G5: 46309 | H5: 46309 | I5: Confirmed | J5: =IF(G5="","",DATE(YEAR(G5),MONTH(G5),1)) -> 46296 | K5: =IF(G5="","",IF(G5<DATE(2027,2,1),"Semester 1","Semester 2")) -> Semester 1 | L5: =IF(I5="Confirmed",TEXT(G5,"ddd"),"TBC") -> Wed | M5: 5:00 PM | N5: Teachers | O5: English | P5: Online - Classera Innovation Platform | Q5: Online | T5: =IF(TRIM(S5)="","Missing","Published") -> Missing | U5: Confirmed | V5: Not started | Z5: =IF(N(X5)>0,N(Y5)/X5,"") | AE5: =IF(G5="","",IF(H5<TODAY(),"Past",IF(G5<=TODAY(),"In progress",IF(G5-TODAY()<=14,"Next 14 days",IF(G5-TODAY()<=45,"Next 45 days","Later"))))) -> Next 14 days | AF5: =IF(G5="","",IF(H5<TODAY(),"",G5-TODAY())) -> 13 | AG5: =IF(AND(AE5="Past",U5<>"Delivered",U5<>"Cancelled",U5<>"Postponed"),"Update status",IF(AND(T5="Missing",OR(AE5="In progress",AE5="Next 14 days")),"Add link",IF(AND(AE5="Next 14 days",V5<>"Published"),"Announce",""))) -> Add link
A6: PD-S03 | B6: Professional Development | C6: EdTech Partner | D6: From Explanation to Experiment: Transforming Science Teaching with Virtual Labs | E6: من الشرح إلى التجربة: تحويل تدريس العلوم بالمعامل الافتراضية | F6: Vlaby | G6: 46323 | H6: 46323 | I6: Confirmed | J6: =IF(G6="","",DATE(YEAR(G6),MONTH(G6),1)) -> 46296 | K6: =IF(G6="","",IF(G6<DATE(2027,2,1),"Semester 1","Semester 2")) -> Semester 1 | L6: =IF(I6="Confirmed",TEXT(G6,"ddd"),"TBC") -> Wed | M6: 5:00 PM | N6: Teachers & Supervisors | O6: Arabic | P6: Online - Classera Innovation Platform | Q6: Online | T6: =IF(TRIM(S6)="","Missing","Published") -> Missing | U6: Confirmed | V6: Not started | Z6: =IF(N(X6)>0,N(Y6)/X6,"") | AE6: =IF(G6="","",IF(H6<TODAY(),"Past",IF(G6<=TODAY(),"In progress",IF(G6-TODAY()<=14,"Next 14 days",IF(G6-TODAY()<=45,"Next 45 days","Later"))))) -> Next 45 days | AF6: =IF(G6="","",IF(H6<TODAY(),"",G6-TODAY())) -> 27 | AG6: =IF(AND(AE6="Past",U6<>"Delivered",U6<>"Cancelled",U6<>"Postponed"),"Update status",IF(AND(T6="Missing",OR(AE6="In progress",AE6="Next 14 days")),"Add link",IF(AND(AE6="Next 14 days",V6<>"Published"),"Announce","")))
A7: PD-S04 | B7: Professional Development | C7: EdTech Partner | D7: Empower Every Learner | E7: تمكين كل متعلم | F7: University Startup | G7: 46337 | H7: 46337 | I7: Confirmed | J7: =IF(G7="","",DATE(YEAR(G7),MONTH(G7),1)) -> 46327 | K7: =IF(G7="","",IF(G7<DATE(2027,2,1),"Semester 1","Semester 2")) -> Semester 1 | L7: =IF(I7="Confirmed",TEXT(G7,"ddd"),"TBC") -> Wed | M7: 5:00 PM | N7: Teachers & Supervisors | O7: English | P7: Online - Classera Innovation Platform | Q7: Online | T7: =IF(TRIM(S7)="","Missing","Published") -> Missing | U7: Confirmed | V7: Not started | Z7: =IF(N(X7)>0,N(Y7)/X7,"") | AE7: =IF(G7="","",IF(H7<TODAY(),"Past",IF(G7<=TODAY(),"In progress",IF(G7-TODAY()<=14,"Next 14 days",IF(G7-TODAY()<=45,"Next 45 days","Later"))))) -> Next 45 days | AF7: =IF(G7="","",IF(H7<TODAY(),"",G7-TODAY())) -> 41 | AG7: =IF(AND(AE7="Past",U7<>"Delivered",U7<>"Cancelled",U7<>"Postponed"),"Update status",IF(AND(T7="Missing",OR(AE7="In progress",AE7="Next 14 days")),"Add link",IF(AND(AE7="Next 14 days",V7<>"Published"),"Announce","")))
A8: PD-S05 | B8: Professional Development | C8: Intel SFI | D8: Intel Skills for Innovation (SFI) Webinar 2: AI Professional Development | E8: Intel Skills for Innovation: التطوير المهني في الذكاء الاصطناعي (2) | F8: Intel | G8: 46365 | H8: 46365 | I8: Confirmed | J8: =IF(G8="","",DATE(YEAR(G8),MONTH(G8),1)) -> 46357 | K8: =IF(G8="","",IF(G8<DATE(2027,2,1),"Semester 1","Semester 2")) -> Semester 1 | L8: =IF(I8="Confirmed",TEXT(G8,"ddd"),"TBC") -> Wed | M8: 5:00 PM | N8: Teachers | O8: English | P8: Online - Classera Innovation Platform | Q8: Online | T8: =IF(TRIM(S8)="","Missing","Published") -> Missing | U8: Confirmed | V8: Not started | Z8: =IF(N(X8)>0,N(Y8)/X8,"") | AE8: =IF(G8="","",IF(H8<TODAY(),"Past",IF(G8<=TODAY(),"In progress",IF(G8-TODAY()<=14,"Next 14 days",IF(G8-TODAY()<=45,"Next 45 days","Later"))))) -> Later | AF8: =IF(G8="","",IF(H8<TODAY(),"",G8-TODAY())) -> 69 | AG8: =IF(AND(AE8="Past",U8<>"Delivered",U8<>"Cancelled",U8<>"Postponed"),"Update status",IF(AND(T8="Missing",OR(AE8="In progress",AE8="Next 14 days")),"Add link",IF(AND(AE8="Next 14 days",V8<>"Published"),"Announce","")))
A9: PD-S06 | B9: Professional Development | C9: EdTech Partner | D9: How do AI-powered solutions measure adaptive-learning outcomes? | E9: كيف تقيس الحلول المدعومة بالذكاء الاصطناعي مخرجات التعلم التكيفي؟ | F9: AILA | G9: 46379 | H9: 46379 | I9: Confirmed | J9: =IF(G9="","",DATE(YEAR(G9),MONTH(G9),1)) -> 46357 | K9: =IF(G9="","",IF(G9<DATE(2027,2,1),"Semester 1","Semester 2")) -> Semester 1 | L9: =IF(I9="Confirmed",TEXT(G9,"ddd"),"TBC") -> Wed | M9: 5:00 PM | N9: Teachers & Supervisors | O9: Arabic | P9: Online - Classera Innovation Platform | Q9: Online | T9: =IF(TRIM(S9)="","Missing","Published") -> Missing | U9: Confirmed | V9: Not started | Z9: =IF(N(X9)>0,N(Y9)/X9,"") | AE9: =IF(G9="","",IF(H9<TODAY(),"Past",IF(G9<=TODAY(),"In progress",IF(G9-TODAY()<=14,"Next 14 days",IF(G9-TODAY()<=45,"Next 45 days","Later"))))) -> Later | AF9: =IF(G9="","",IF(H9<TODAY(),"",G9-TODAY())) -> 83 | AG9: =IF(AND(AE9="Past",U9<>"Delivered",U9<>"Cancelled",U9<>"Postponed"),"Update status",IF(AND(T9="Missing",OR(AE9="In progress",AE9="Next 14 days")),"Add link",IF(AND(AE9="Next 14 days",V9<>"Published"),"Announce","")))
A10: PD-S07 | B10: Professional Development | C10: Intel SFI | D10: Intel Skills for Innovation (SFI) Webinar 3: AI Professional Development | E10: Intel Skills for Innovation: التطوير المهني في الذكاء الاصطناعي (3) | F10: Intel | G10: 46463 | H10: 46463 | I10: Confirmed | J10: =IF(G10="","",DATE(YEAR(G10),MONTH(G10),1)) -> 46447 | K10: =IF(G10="","",IF(G10<DATE(2027,2,1),"Semester 1","Semester 2")) -> Semester 2 | L10: =IF(I10="Confirmed",TEXT(G10,"ddd"),"TBC") -> Wed | M10: 5:00 PM | N10: Teachers | O10: English | P10: Online - Classera Innovation Platform | Q10: Online | T10: =IF(TRIM(S10)="","Missing","Published") -> Missing | U10: Confirmed | V10: Not started | Z10: =IF(N(X10)>0,N(Y10)/X10,"") | AE10: =IF(G10="","",IF(H10<TODAY(),"Past",IF(G10<=TODAY(),"In progress",IF(G10-TODAY()<=14,"Next 14 days",IF(G10-TODAY()<=45,"Next 45 days","Later"))))) -> Later | AF10: =IF(G10="","",IF(H10<TODAY(),"",G10-TODAY())) -> 167 | AG10: =IF(AND(AE10="Past",U10<>"Delivered",U10<>"Cancelled",U10<>"Postponed"),"Update status",IF(AND(T10="Missing",OR(AE10="In progress",AE10="Next 14 days")),"Add link",IF(AND(AE10="Next 14 days",V10<>"Published"),"Announce","")))
A11: PD-S08 | B11: Professional Development | C11: Classera LMS | D11: Classera LMS Updates | E11: تحديثات نظام كلاسيرا | F11: Classera Product Team | G11: 46477 | H11: 46477 | I11: Confirmed | J11: =IF(G11="","",DATE(YEAR(G11),MONTH(G11),1)) -> 46447 | K11: =IF(G11="","",IF(G11<DATE(2027,2,1),"Semester 1","Semester 2")) -> Semester 2 | L11: =IF(I11="Confirmed",TEXT(G11,"ddd"),"TBC") -> Wed | M11: 5:00 PM | N11: All LMS Users | O11: Arabic | P11: Online - Classera Innovation Platform | Q11: Online | T11: =IF(TRIM(S11)="","Missing","Published") -> Missing | U11: Confirmed | V11: Not started | Z11: =IF(N(X11)>0,N(Y11)/X11,"") | AE11: =IF(G11="","",IF(H11<TODAY(),"Past",IF(G11<=TODAY(),"In progress",IF(G11-TODAY()<=14,"Next 14 days",IF(G11-TODAY()<=45,"Next 45 days","Later"))))) -> Later | AF11: =IF(G11="","",IF(H11<TODAY(),"",G11-TODAY())) -> 181 | AG11: =IF(AND(AE11="Past",U11<>"Delivered",U11<>"Cancelled",U11<>"Postponed"),"Update status",IF(AND(T11="Missing",OR(AE11="In progress",AE11="Next 14 days")),"Add link",IF(AND(AE11="Next 14 days",V11<>"Published"),"Announce","")))
A12: PD-S09 | B12: Professional Development | C12: EdTech Partner | D12: Technology in Education Webinar Series: Session 4 | E12: سلسلة تقنيات التعليم: الجلسة الرابعة | F12: TBC | G12: 46484 | H12: 46484 | I12: Confirmed | J12: =IF(G12="","",DATE(YEAR(G12),MONTH(G12),1)) -> 46478 | K12: =IF(G12="","",IF(G12<DATE(2027,2,1),"Semester 1","Semester 2")) -> Semester 2 | L12: =IF(I12="Confirmed",TEXT(G12,"ddd"),"TBC") -> Wed | M12: 5:00 PM | N12: Teachers & Supervisors | P12: Online - Classera Innovation Platform | Q12: Online | T12: =IF(TRIM(S12)="","Missing","Published") -> Missing | U12: Confirmed | V12: Not started | Z12: =IF(N(X12)>0,N(Y12)/X12,"") | AE12: =IF(G12="","",IF(H12<TODAY(),"Past",IF(G12<=TODAY(),"In progress",IF(G12-TODAY()<=14,"Next 14 days",IF(G12-TODAY()<=45,"Next 45 days","Later"))))) -> Later | AF12: =IF(G12="","",IF(H12<TODAY(),"",G12-TODAY())) -> 188 | AG12: =IF(AND(AE12="Past",U12<>"Delivered",U12<>"Cancelled",U12<>"Postponed"),"Update status",IF(AND(T12="Missing",OR(AE12="In progress",AE12="Next 14 days")),"Add link",IF(AND(AE12="Next 14 days",V12<>"Published"),"Announce","")))
A13: PD-S10 | B13: Professional Development | C13: EdTech Partner | D13: Technology in Education Webinar Series: Session 5 | E13: سلسلة تقنيات التعليم: الجلسة الخامسة | F13: TBC | G13: 46498 | H13: 46498 | I13: Confirmed | J13: =IF(G13="","",DATE(YEAR(G13),MONTH(G13),1)) -> 46478 | K13: =IF(G13="","",IF(G13<DATE(2027,2,1),"Semester 1","Semester 2")) -> Semester 2 | L13: =IF(I13="Confirmed",TEXT(G13,"ddd"),"TBC") -> Wed | M13: 5:00 PM | N13: Teachers & Supervisors | P13: Online - Classera Innovation Platform | Q13: Online | T13: =IF(TRIM(S13)="","Missing","Published") -> Missing | U13: Confirmed | V13: Not started | Z13: =IF(N(X13)>0,N(Y13)/X13,"") | AE13: =IF(G13="","",IF(H13<TODAY(),"Past",IF(G13<=TODAY(),"In progress",IF(G13-TODAY()<=14,"Next 14 days",IF(G13-TODAY()<=45,"Next 45 days","Later"))))) -> Later | AF13: =IF(G13="","",IF(H13<TODAY(),"",G13-TODAY())) -> 202 | AG13: =IF(AND(AE13="Past",U13<>"Delivered",U13<>"Cancelled",U13<>"Postponed"),"Update status",IF(AND(T13="Missing",OR(AE13="In progress",AE13="Next 14 days")),"Add link",IF(AND(AE13="Next 14 days",V13<>"Published"),"Announce","")))
A14: PD-S11 | B14: Professional Development | C14: EdTech Partner | D14: Technology in Education Webinar Series: Session 6 | E14: سلسلة تقنيات التعليم: الجلسة السادسة | F14: TBC | G14: 46512 | H14: 46512 | I14: Confirmed | J14: =IF(G14="","",DATE(YEAR(G14),MONTH(G14),1)) -> 46508 | K14: =IF(G14="","",IF(G14<DATE(2027,2,1),"Semester 1","Semester 2")) -> Semester 2 | L14: =IF(I14="Confirmed",TEXT(G14,"ddd"),"TBC") -> Wed | M14: 5:00 PM | N14: Teachers & Supervisors | P14: Online - Classera Innovation Platform | Q14: Online | T14: =IF(TRIM(S14)="","Missing","Published") -> Missing | U14: Confirmed | V14: Not started | Z14: =IF(N(X14)>0,N(Y14)/X14,"") | AE14: =IF(G14="","",IF(H14<TODAY(),"Past",IF(G14<=TODAY(),"In progress",IF(G14-TODAY()<=14,"Next 14 days",IF(G14-TODAY()<=45,"Next 45 days","Later"))))) -> Later | AF14: =IF(G14="","",IF(H14<TODAY(),"",G14-TODAY())) -> 216 | AG14: =IF(AND(AE14="Past",U14<>"Delivered",U14<>"Cancelled",U14<>"Postponed"),"Update status",IF(AND(T14="Missing",OR(AE14="In progress",AE14="Next 14 days")),"Add link",IF(AND(AE14="Next 14 days",V14<>"Published"),"Announce","")))
A15: ACC-01 | B15: Accreditation | C15: Exam Window | D15: Accreditation Exam Window: September 2026 (Period 1) | E15: فترة اختبارات الاعتماد: سبتمبر 2026 (الفترة 1) | F15: Classera & Intel | G15: 46286 | H15: 46292 | I15: Confirmed | J15: =IF(G15="","",DATE(YEAR(G15),MONTH(G15),1)) -> 46266 | K15: =IF(G15="","",IF(G15<DATE(2027,2,1),"Semester 1","Semester 2")) -> Semester 1 | L15: =IF(I15="Confirmed",TEXT(G15,"ddd"),"TBC") -> Mon | N15: Educators (Teachers, School Leaders, System Managers) | P15: Online - Accreditation Platform | Q15: Online | S15: https://accreditation.classera.com/ | T15: =IF(TRIM(S15)="","Missing","Published") -> Published | U15: Registration Open | V15: Not started | Z15: =IF(N(X15)>0,N(Y15)/X15,"") | AE15: =IF(G15="","",IF(H15<TODAY(),"Past",IF(G15<=TODAY(),"In progress",IF(G15-TODAY()<=14,"Next 14 days",IF(G15-TODAY()<=45,"Next 45 days","Later"))))) -> Past | AF15: =IF(G15="","",IF(H15<TODAY(),"",G15-TODAY())) | AG15: =IF(AND(AE15="Past",U15<>"Delivered",U15<>"Cancelled",U15<>"Postponed"),"Update status",IF(AND(T15="Missing",OR(AE15="In progress",AE15="Next 14 days")),"Add link",IF(AND(AE15="Next 14 days",V15<>"Published"),"Announce",""))) -> Update status
A16: ACC-02 | B16: Accreditation | C16: Exam Window | D16: Accreditation Exam Window: October 2026 (Period 1) | E16: فترة اختبارات الاعتماد: أكتوبر 2026 (الفترة 1) | F16: Classera & Intel | G16: 46300 | H16: 46306 | I16: Confirmed | J16: =IF(G16="","",DATE(YEAR(G16),MONTH(G16),1)) -> 46296 | K16: =IF(G16="","",IF(G16<DATE(2027,2,1),"Semester 1","Semester 2")) -> Semester 1 | L16: =IF(I16="Confirmed",TEXT(G16,"ddd"),"TBC") -> Mon | N16: Educators (Teachers, School Leaders, System Managers) | P16: Online - Accreditation Platform | Q16: Online | S16: https://accreditation.classera.com/ | T16: =IF(TRIM(S16)="","Missing","Published") -> Published | U16: Registration Open | V16: Not started | Z16: =IF(N(X16)>0,N(Y16)/X16,"") | AE16: =IF(G16="","",IF(H16<TODAY(),"Past",IF(G16<=TODAY(),"In progress",IF(G16-TODAY()<=14,"Next 14 days",IF(G16-TODAY()<=45,"Next 45 days","Later"))))) -> Next 14 days | AF16: =IF(G16="","",IF(H16<TODAY(),"",G16-TODAY())) -> 4 | AG16: =IF(AND(AE16="Past",U16<>"Delivered",U16<>"Cancelled",U16<>"Postponed"),"Update status",IF(AND(T16="Missing",OR(AE16="In progress",AE16="Next 14 days")),"Add link",IF(AND(AE16="Next 14 days",V16<>"Published"),"Announce",""))) -> Announce
A17: ACC-03 | B17: Accreditation | C17: Exam Window | D17: Accreditation Exam Window: October 2026 (Period 2) | E17: فترة اختبارات الاعتماد: أكتوبر 2026 (الفترة 2) | F17: Classera & Intel | G17: 46314 | H17: 46320 | I17: Confirmed | J17: =IF(G17="","",DATE(YEAR(G17),MONTH(G17),1)) -> 46296 | K17: =IF(G17="","",IF(G17<DATE(2027,2,1),"Semester 1","Semester 2")) -> Semester 1 | L17: =IF(I17="Confirmed",TEXT(G17,"ddd"),"TBC") -> Mon | N17: Educators (Teachers, School Leaders, System Managers) | P17: Online - Accreditation Platform | Q17: Online | S17: https://accreditation.classera.com/ | T17: =IF(TRIM(S17)="","Missing","Published") -> Published | U17: Registration Open | V17: Not started | Z17: =IF(N(X17)>0,N(Y17)/X17,"") | AE17: =IF(G17="","",IF(H17<TODAY(),"Past",IF(G17<=TODAY(),"In progress",IF(G17-TODAY()<=14,"Next 14 days",IF(G17-TODAY()<=45,"Next 45 days","Later"))))) -> Next 45 days | AF17: =IF(G17="","",IF(H17<TODAY(),"",G17-TODAY())) -> 18 | AG17: =IF(AND(AE17="Past",U17<>"Delivered",U17<>"Cancelled",U17<>"Postponed"),"Update status",IF(AND(T17="Missing",OR(AE17="In progress",AE17="Next 14 days")),"Add link",IF(AND(AE17="Next 14 days",V17<>"Published"),"Announce","")))
A18: ACC-04 | B18: Accreditation | C18: Exam Window | D18: Accreditation Exam Window: November 2026 (Period 1) | E18: فترة اختبارات الاعتماد: نوفمبر 2026 (الفترة 1) | F18: Classera & Intel | G18: 46335 | H18: 46341 | I18: Confirmed | J18: =IF(G18="","",DATE(YEAR(G18),MONTH(G18),1)) -> 46327 | K18: =IF(G18="","",IF(G18<DATE(2027,2,1),"Semester 1","Semester 2")) -> Semester 1 | L18: =IF(I18="Confirmed",TEXT(G18,"ddd"),"TBC") -> Mon | N18: Educators (Teachers, School Leaders, System Managers) | P18: Online - Accreditation Platform | Q18: Online | S18: https://accreditation.classera.com/ | T18: =IF(TRIM(S18)="","Missing","Published") -> Published | U18: Registration Open | V18: Not started | Z18: =IF(N(X18)>0,N(Y18)/X18,"") | AE18: =IF(G18="","",IF(H18<TODAY(),"Past",IF(G18<=TODAY(),"In progress",IF(G18-TODAY()<=14,"Next 14 days",IF(G18-TODAY()<=45,"Next 45 days","Later"))))) -> Next 45 days | AF18: =IF(G18="","",IF(H18<TODAY(),"",G18-TODAY())) -> 39 | AG18: =IF(AND(AE18="Past",U18<>"Delivered",U18<>"Cancelled",U18<>"Postponed"),"Update status",IF(AND(T18="Missing",OR(AE18="In progress",AE18="Next 14 days")),"Add link",IF(AND(AE18="Next 14 days",V18<>"Published"),"Announce","")))
A19: ACC-05 | B19: Accreditation | C19: Exam Window | D19: Accreditation Exam Window: November 2026 (Period 2) | E19: فترة اختبارات الاعتماد: نوفمبر 2026 (الفترة 2) | F19: Classera & Intel | G19: 46349 | H19: 46355 | I19: Confirmed | J19: =IF(G19="","",DATE(YEAR(G19),MONTH(G19),1)) -> 46327 | K19: =IF(G19="","",IF(G19<DATE(2027,2,1),"Semester 1","Semester 2")) -> Semester 1 | L19: =IF(I19="Confirmed",TEXT(G19,"ddd"),"TBC") -> Mon | N19: Educators (Teachers, School Leaders, System Managers) | P19: Online - Accreditation Platform | Q19: Online | S19: https://accreditation.classera.com/ | T19: =IF(TRIM(S19)="","Missing","Published") -> Published | U19: Registration Open | V19: Not started | Z19: =IF(N(X19)>0,N(Y19)/X19,"") | AE19: =IF(G19="","",IF(H19<TODAY(),"Past",IF(G19<=TODAY(),"In progress",IF(G19-TODAY()<=14,"Next 14 days",IF(G19-TODAY()<=45,"Next 45 days","Later"))))) -> Later | AF19: =IF(G19="","",IF(H19<TODAY(),"",G19-TODAY())) -> 53 | AG19: =IF(AND(AE19="Past",U19<>"Delivered",U19<>"Cancelled",U19<>"Postponed"),"Update status",IF(AND(T19="Missing",OR(AE19="In progress",AE19="Next 14 days")),"Add link",IF(AND(AE19="Next 14 days",V19<>"Published"),"Announce","")))
A20: ACC-06 | B20: Accreditation | C20: Exam Window | D20: Accreditation Exam Window: December 2026 (Period 1) | E20: فترة اختبارات الاعتماد: ديسمبر 2026 (الفترة 1) | F20: Classera & Intel | G20: 46363 | H20: 46369 | I20: Confirmed | J20: =IF(G20="","",DATE(YEAR(G20),MONTH(G20),1)) -> 46357 | K20: =IF(G20="","",IF(G20<DATE(2027,2,1),"Semester 1","Semester 2")) -> Semester 1 | L20: =IF(I20="Confirmed",TEXT(G20,"ddd"),"TBC") -> Mon | N20: Educators (Teachers, School Leaders, System Managers) | P20: Online - Accreditation Platform | Q20: Online | S20: https://accreditation.classera.com/ | T20: =IF(TRIM(S20)="","Missing","Published") -> Published | U20: Registration Open | V20: Not started | Z20: =IF(N(X20)>0,N(Y20)/X20,"") | AE20: =IF(G20="","",IF(H20<TODAY(),"Past",IF(G20<=TODAY(),"In progress",IF(G20-TODAY()<=14,"Next 14 days",IF(G20-TODAY()<=45,"Next 45 days","Later"))))) -> Later | AF20: =IF(G20="","",IF(H20<TODAY(),"",G20-TODAY())) -> 67 | AG20: =IF(AND(AE20="Past",U20<>"Delivered",U20<>"Cancelled",U20<>"Postponed"),"Update status",IF(AND(T20="Missing",OR(AE20="In progress",AE20="Next 14 days")),"Add link",IF(AND(AE20="Next 14 days",V20<>"Published"),"Announce","")))
A21: ACC-07 | B21: Accreditation | C21: Exam Window | D21: Accreditation Exam Window: December 2026 (Period 2) | E21: فترة اختبارات الاعتماد: ديسمبر 2026 (الفترة 2) | F21: Classera & Intel | G21: 46377 | H21: 46383 | I21: Confirmed | J21: =IF(G21="","",DATE(YEAR(G21),MONTH(G21),1)) -> 46357 | K21: =IF(G21="","",IF(G21<DATE(2027,2,1),"Semester 1","Semester 2")) -> Semester 1 | L21: =IF(I21="Confirmed",TEXT(G21,"ddd"),"TBC") -> Mon | N21: Educators (Teachers, School Leaders, System Managers) | P21: Online - Accreditation Platform | Q21: Online | S21: https://accreditation.classera.com/ | T21: =IF(TRIM(S21)="","Missing","Published") -> Published | U21: Registration Open | V21: Not started | Z21: =IF(N(X21)>0,N(Y21)/X21,"") | AE21: =IF(G21="","",IF(H21<TODAY(),"Past",IF(G21<=TODAY(),"In progress",IF(G21-TODAY()<=14,"Next 14 days",IF(G21-TODAY()<=45,"Next 45 days","Later"))))) -> Later | AF21: =IF(G21="","",IF(H21<TODAY(),"",G21-TODAY())) -> 81 | AG21: =IF(AND(AE21="Past",U21<>"Delivered",U21<>"Cancelled",U21<>"Postponed"),"Update status",IF(AND(T21="Missing",OR(AE21="In progress",AE21="Next 14 days")),"Add link",IF(AND(AE21="Next 14 days",V21<>"Published"),"Announce","")))
A22: ACC-08 | B22: Accreditation | C22: Exam Window | D22: Accreditation Exam Window: January 2027 (Period 1) | E22: فترة اختبارات الاعتماد: يناير 2027 (الفترة 1) | F22: Classera & Intel | G22: 46391 | H22: 46397 | I22: Confirmed | J22: =IF(G22="","",DATE(YEAR(G22),MONTH(G22),1)) -> 46388 | K22: =IF(G22="","",IF(G22<DATE(2027,2,1),"Semester 1","Semester 2")) -> Semester 1 | L22: =IF(I22="Confirmed",TEXT(G22,"ddd"),"TBC") -> Mon | N22: Educators (Teachers, School Leaders, System Managers) | P22: Online - Accreditation Platform | Q22: Online | S22: https://accreditation.classera.com/ | T22: =IF(TRIM(S22)="","Missing","Published") -> Published | U22: Registration Open | V22: Not started | Z22: =IF(N(X22)>0,N(Y22)/X22,"") | AE22: =IF(G22="","",IF(H22<TODAY(),"Past",IF(G22<=TODAY(),"In progress",IF(G22-TODAY()<=14,"Next 14 days",IF(G22-TODAY()<=45,"Next 45 days","Later"))))) -> Later | AF22: =IF(G22="","",IF(H22<TODAY(),"",G22-TODAY())) -> 95 | AG22: =IF(AND(AE22="Past",U22<>"Delivered",U22<>"Cancelled",U22<>"Postponed"),"Update status",IF(AND(T22="Missing",OR(AE22="In progress",AE22="Next 14 days")),"Add link",IF(AND(AE22="Next 14 days",V22<>"Published"),"Announce","")))
A23: ACC-09 | B23: Accreditation | C23: Exam Window | D23: Accreditation Exam Window: January 2027 (Period 2) | E23: فترة اختبارات الاعتماد: يناير 2027 (الفترة 2) | F23: Classera & Intel | G23: 46405 | H23: 46411 | I23: Confirmed | J23: =IF(G23="","",DATE(YEAR(G23),MONTH(G23),1)) -> 46388 | K23: =IF(G23="","",IF(G23<DATE(2027,2,1),"Semester 1","Semester 2")) -> Semester 1 | L23: =IF(I23="Confirmed",TEXT(G23,"ddd"),"TBC") -> Mon | N23: Educators (Teachers, School Leaders, System Managers) | P23: Online - Accreditation Platform | Q23: Online | S23: https://accreditation.classera.com/ | T23: =IF(TRIM(S23)="","Missing","Published") -> Published | U23: Registration Open | V23: Not started | Z23: =IF(N(X23)>0,N(Y23)/X23,"") | AE23: =IF(G23="","",IF(H23<TODAY(),"Past",IF(G23<=TODAY(),"In progress",IF(G23-TODAY()<=14,"Next 14 days",IF(G23-TODAY()<=45,"Next 45 days","Later"))))) -> Later | AF23: =IF(G23="","",IF(H23<TODAY(),"",G23-TODAY())) -> 109 | AG23: =IF(AND(AE23="Past",U23<>"Delivered",U23<>"Cancelled",U23<>"Postponed"),"Update status",IF(AND(T23="Missing",OR(AE23="In progress",AE23="Next 14 days")),"Add link",IF(AND(AE23="Next 14 days",V23<>"Published"),"Announce","")))
A24: ACC-10 | B24: Accreditation | C24: Exam Window | D24: Accreditation Exam Window: February 2027 (Period 1) | E24: فترة اختبارات الاعتماد: فبراير 2027 (الفترة 1) | F24: Classera & Intel | G24: 46426 | H24: 46432 | I24: Confirmed | J24: =IF(G24="","",DATE(YEAR(G24),MONTH(G24),1)) -> 46419 | K24: =IF(G24="","",IF(G24<DATE(2027,2,1),"Semester 1","Semester 2")) -> Semester 2 | L24: =IF(I24="Confirmed",TEXT(G24,"ddd"),"TBC") -> Mon | N24: Educators (Teachers, School Leaders, System Managers) | P24: Online - Accreditation Platform | Q24: Online | S24: https://accreditation.classera.com/ | T24: =IF(TRIM(S24)="","Missing","Published") -> Published | U24: Registration Open | V24: Not started | Z24: =IF(N(X24)>0,N(Y24)/X24,"") | AE24: =IF(G24="","",IF(H24<TODAY(),"Past",IF(G24<=TODAY(),"In progress",IF(G24-TODAY()<=14,"Next 14 days",IF(G24-TODAY()<=45,"Next 45 days","Later"))))) -> Later | AF24: =IF(G24="","",IF(H24<TODAY(),"",G24-TODAY())) -> 130 | AG24: =IF(AND(AE24="Past",U24<>"Delivered",U24<>"Cancelled",U24<>"Postponed"),"Update status",IF(AND(T24="Missing",OR(AE24="In progress",AE24="Next 14 days")),"Add link",IF(AND(AE24="Next 14 days",V24<>"Published"),"Announce","")))
A25: ACC-11 | B25: Accreditation | C25: Exam Window | D25: Accreditation Exam Window: February 2027 (Period 2) | E25: فترة اختبارات الاعتماد: فبراير 2027 (الفترة 2) | F25: Classera & Intel | G25: 46440 | H25: 46446 | I25: Confirmed | J25: =IF(G25="","",DATE(YEAR(G25),MONTH(G25),1)) -> 46419 | K25: =IF(G25="","",IF(G25<DATE(2027,2,1),"Semester 1","Semester 2")) -> Semester 2 | L25: =IF(I25="Confirmed",TEXT(G25,"ddd"),"TBC") -> Mon | N25: Educators (Teachers, School Leaders, System Managers) | P25: Online - Accreditation Platform | Q25: Online | S25: https://accreditation.classera.com/ | T25: =IF(TRIM(S25)="","Missing","Published") -> Published | U25: Registration Open | V25: Not started | Z25: =IF(N(X25)>0,N(Y25)/X25,"") | AE25: =IF(G25="","",IF(H25<TODAY(),"Past",IF(G25<=TODAY(),"In progress",IF(G25-TODAY()<=14,"Next 14 days",IF(G25-TODAY()<=45,"Next 45 days","Later"))))) -> Later | AF25: =IF(G25="","",IF(H25<TODAY(),"",G25-TODAY())) -> 144 | AG25: =IF(AND(AE25="Past",U25<>"Delivered",U25<>"Cancelled",U25<>"Postponed"),"Update status",IF(AND(T25="Missing",OR(AE25="In progress",AE25="Next 14 days")),"Add link",IF(AND(AE25="Next 14 days",V25<>"Published"),"Announce","")))
A26: ACC-12 | B26: Accreditation | C26: Exam Window | D26: Accreditation Exam Window: March 2027 (Period 1) | E26: فترة اختبارات الاعتماد: مارس 2027 (الفترة 1) | F26: Classera & Intel | G26: 46454 | H26: 46460 | I26: Confirmed | J26: =IF(G26="","",DATE(YEAR(G26),MONTH(G26),1)) -> 46447 | K26: =IF(G26="","",IF(G26<DATE(2027,2,1),"Semester 1","Semester 2")) -> Semester 2 | L26: =IF(I26="Confirmed",TEXT(G26,"ddd"),"TBC") -> Mon | N26: Educators (Teachers, School Leaders, System Managers) | P26: Online - Accreditation Platform | Q26: Online | S26: https://accreditation.classera.com/ | T26: =IF(TRIM(S26)="","Missing","Published") -> Published | U26: Registration Open | V26: Not started | Z26: =IF(N(X26)>0,N(Y26)/X26,"") | AE26: =IF(G26="","",IF(H26<TODAY(),"Past",IF(G26<=TODAY(),"In progress",IF(G26-TODAY()<=14,"Next 14 days",IF(G26-TODAY()<=45,"Next 45 days","Later"))))) -> Later | AF26: =IF(G26="","",IF(H26<TODAY(),"",G26-TODAY())) -> 158 | AG26: =IF(AND(AE26="Past",U26<>"Delivered",U26<>"Cancelled",U26<>"Postponed"),"Update status",IF(AND(T26="Missing",OR(AE26="In progress",AE26="Next 14 days")),"Add link",IF(AND(AE26="Next 14 days",V26<>"Published"),"Announce","")))
... A33: ACC-19 | B33: Accreditation | C33: Exam Window | D33: Accreditation Exam Window: June 2027 (Period 2) | E33: فترة اختبارات الاعتماد: يونيو 2027 (الفترة 2) | F33: Classera & Intel | G33: 46559 | H33: 46565 | I33: Confirmed | J33: =IF(G33="","",DATE(YEAR(G33),MONTH(G33),1)) -> 46539 | K33: =IF(G33="","",IF(G33<DATE(2027,2,1),"Semester 1","Semester 2")) -> Semester 2 | L33: =IF(I33="Confirmed",TEXT(G33,"ddd"),"TBC") -> Mon | N33: Educators (Teachers, School Leaders, System Managers) | P33: Online - Accreditation Platform | Q33: Online | S33: https://accreditation.classera.com/ | T33: =IF(TRIM(S33)="","Missing","Published") -> Published | U33: Registration Open | V33: Not started | Z33: =IF(N(X33)>0,N(Y33)/X33,"") | AE33: =IF(G33="","",IF(H33<TODAY(),"Past",IF(G33<=TODAY(),"In progress",IF(G33-TODAY()<=14,"Next 14 days",IF(G33-TODAY()<=45,"Next 45 days","Later"))))) -> Later | AF33: =IF(G33="","",IF(H33<TODAY(),"",G33-TODAY())) -> 263 | AG33: =IF(AND(AE33="Past",U33<>"Delivered",U33<>"Cancelled",U33<>"Postponed"),"Update status",IF(AND(T33="Missing",OR(AE33="In progress",AE33="Next 14 days")),"Add link",IF(AND(AE33="Next 14 days",V33<>"Published"),"Announce","")))
A34: ENR-01 | B34: Enrichment Academy | C34: National & Awareness | D34: Saudi National Day Activities | E34: فعاليات اليوم الوطني | F34: Enrichment Academy | G34: 46286 | H34: 46286 | I34: Confirmed | J34: =IF(G34="","",DATE(YEAR(G34),MONTH(G34),1)) -> 46266 | K34: =IF(G34="","",IF(G34<DATE(2027,2,1),"Semester 1","Semester 2")) -> Semester 1 | L34: =IF(I34="Confirmed",TEXT(G34,"ddd"),"TBC") -> Mon | N34: All grades | P34: Saudi Arabia | Q34: Online | R34: Free | S34: https://sh.classera.com/NationalDay | T34: =IF(TRIM(S34)="","Missing","Published") -> Published | U34: Registration Open | V34: Not started | Z34: =IF(N(X34)>0,N(Y34)/X34,"") | AE34: =IF(G34="","",IF(H34<TODAY(),"Past",IF(G34<=TODAY(),"In progress",IF(G34-TODAY()<=14,"Next 14 days",IF(G34-TODAY()<=45,"Next 45 days","Later"))))) -> Past | AF34: =IF(G34="","",IF(H34<TODAY(),"",G34-TODAY())) | AG34: =IF(AND(AE34="Past",U34<>"Delivered",U34<>"Cancelled",U34<>"Postponed"),"Update status",IF(AND(T34="Missing",OR(AE34="In progress",AE34="Next 14 days")),"Add link",IF(AND(AE34="Next 14 days",V34<>"Published"),"Announce",""))) -> Update status
A35: ENR-02 | B35: Enrichment Academy | C35: National & Awareness | D35: World Teachers' Day | E35: يوم المعلم | F35: Enrichment Academy | G35: 46300 | H35: 46300 | I35: Confirmed | J35: =IF(G35="","",DATE(YEAR(G35),MONTH(G35),1)) -> 46296 | K35: =IF(G35="","",IF(G35<DATE(2027,2,1),"Semester 1","Semester 2")) -> Semester 1 | L35: =IF(I35="Confirmed",TEXT(G35,"ddd"),"TBC") -> Mon | N35: Teachers | P35: Saudi Arabia, Egypt, Jordan, Other countries | Q35: Online | R35: Free | S35: https://iacademy.classera.com/lectures-list/?course_title=يوم%20المعلم%2026-27&course_type=1&c=eyJjb3Vyc2VfaWQiOiIxMjc0MzYifQ | T35: =IF(TRIM(S35)="","Missing","Published") -> Published | U35: Registration Open | V35: Not started | Z35: =IF(N(X35)>0,N(Y35)/X35,"") | AE35: =IF(G35="","",IF(H35<TODAY(),"Past",IF(G35<=TODAY(),"In progress",IF(G35-TODAY()<=14,"Next 14 days",IF(G35-TODAY()<=45,"Next 45 days","Later"))))) -> Next 14 days | AF35: =IF(G35="","",IF(H35<TODAY(),"",G35-TODAY())) -> 4 | AG35: =IF(AND(AE35="Past",U35<>"Delivered",U35<>"Cancelled",U35<>"Postponed"),"Update status",IF(AND(T35="Missing",OR(AE35="In progress",AE35="Next 14 days")),"Add link",IF(AND(AE35="Next 14 days",V35<>"Published"),"Announce",""))) -> Announce
A36: ENR-03 | B36: Enrichment Academy | C36: National & Awareness | D36: October 6 Victory Celebration | E36: فعاليات نصر 6 أكتوبر | F36: Enrichment Academy | G36: 46301 | H36: 46301 | I36: Confirmed | J36: =IF(G36="","",DATE(YEAR(G36),MONTH(G36),1)) -> 46296 | K36: =IF(G36="","",IF(G36<DATE(2027,2,1),"Semester 1","Semester 2")) -> Semester 1 | L36: =IF(I36="Confirmed",TEXT(G36,"ddd"),"TBC") -> Tue | N36: All grades | P36: Egypt | Q36: Online | R36: Free | S36: https://iacademy.classera.com/lectures-list/?course_title=فاعليات%20%20نصر%20اكتوبر%2026-27&course_type=1&c=eyJjb3Vyc2VfaWQiOiIxMjQwNDMifQ | T36: =IF(TRIM(S36)="","Missing","Published") -> Published | U36: Registration Open | V36: Not started | Z36: =IF(N(X36)>0,N(Y36)/X36,"") | AE36: =IF(G36="","",IF(H36<TODAY(),"Past",IF(G36<=TODAY(),"In progress",IF(G36-TODAY()<=14,"Next 14 days",IF(G36-TODAY()<=45,"Next 45 days","Later"))))) -> Next 14 days | AF36: =IF(G36="","",IF(H36<TODAY(),"",G36-TODAY())) -> 5 | AG36: =IF(AND(AE36="Past",U36<>"Delivered",U36<>"Cancelled",U36<>"Postponed"),"Update status",IF(AND(T36="Missing",OR(AE36="In progress",AE36="Next 14 days")),"Add link",IF(AND(AE36="Next 14 days",V36<>"Published"),"Announce",""))) -> Announce
A37: ENR-04 | B37: Enrichment Academy | C37: Skill Courses | D37: Mobile App Programming | E37: مهارات برمجة تطبيقات الجوال | F37: Enrichment Academy | G37: 46307 | H37: 46307 | I37: Confirmed | J37: =IF(G37="","",DATE(YEAR(G37),MONTH(G37),1)) -> 46296 | K37: =IF(G37="","",IF(G37<DATE(2027,2,1),"Semester 1","Semester 2")) -> Semester 1 | L37: =IF(I37="Confirmed",TEXT(G37,"ddd"),"TBC") -> Mon | N37: Middle & Secondary | P37: Saudi Arabia, Egypt, Jordan, Other countries | Q37: Online | R37: Paid (Secondary) | S37: https://iacademy.classera.com/lectures-list/?course_title=مهارات%20برمجة%20تطبيقات%20الجوال%2026-27&course_type=1&c=eyJjb3Vyc2VfaWQiOiIxMjc4MzIifQ | T37: =IF(TRIM(S37)="","Missing","Published") -> Published | U37: Registration Open | V37: Not started | Z37: =IF(N(X37)>0,N(Y37)/X37,"") | AE37: =IF(G37="","",IF(H37<TODAY(),"Past",IF(G37<=TODAY(),"In progress",IF(G37-TODAY()<=14,"Next 14 days",IF(G37-TODAY()<=45,"Next 45 days","Later"))))) -> Next 14 days | AF37: =IF(G37="","",IF(H37<TODAY(),"",G37-TODAY())) -> 11 | AG37: =IF(AND(AE37="Past",U37<>"Delivered",U37<>"Cancelled",U37<>"Postponed"),"Update status",IF(AND(T37="Missing",OR(AE37="In progress",AE37="Next 14 days")),"Add link",IF(AND(AE37="Next 14 days",V37<>"Published"),"Announce",""))) -> Announce
A38: ENR-05 | B38: Enrichment Academy | C38: Skill Courses | D38: Digital Art Fundamentals | E38: أساسيات الرسم الرقمي | F38: Enrichment Academy | G38: 46314 | H38: 46314 | I38: Confirmed | J38: =IF(G38="","",DATE(YEAR(G38),MONTH(G38),1)) -> 46296 | K38: =IF(G38="","",IF(G38<DATE(2027,2,1),"Semester 1","Semester 2")) -> Semester 1 | L38: =IF(I38="Confirmed",TEXT(G38,"ddd"),"TBC") -> Mon | N38: All grades | P38: Saudi Arabia, Egypt, Jordan, Other countries | Q38: Online | R38: Free | T38: =IF(TRIM(S38)="","Missing","Published") -> Missing | U38: Planned | V38: Not started | Z38: =IF(N(X38)>0,N(Y38)/X38,"") | AE38: =IF(G38="","",IF(H38<TODAY(),"Past",IF(G38<=TODAY(),"In progress",IF(G38-TODAY()<=14,"Next 14 days",IF(G38-TODAY()<=45,"Next 45 days","Later"))))) -> Next 45 days | AF38: =IF(G38="","",IF(H38<TODAY(),"",G38-TODAY())) -> 18 | AG38: =IF(AND(AE38="Past",U38<>"Delivered",U38<>"Cancelled",U38<>"Postponed"),"Update status",IF(AND(T38="Missing",OR(AE38="In progress",AE38="Next 14 days")),"Add link",IF(AND(AE38="Next 14 days",V38<>"Published"),"Announce","")))
A39: ENR-06 | B39: Enrichment Academy | C39: National & Awareness | D39: World Savings Day | E39: يوم الادخار العالمي | F39: Enrichment Academy | G39: 46321 | H39: 46321 | I39: Confirmed | J39: =IF(G39="","",DATE(YEAR(G39),MONTH(G39),1)) -> 46296 | K39: =IF(G39="","",IF(G39<DATE(2027,2,1),"Semester 1","Semester 2")) -> Semester 1 | L39: =IF(I39="Confirmed",TEXT(G39,"ddd"),"TBC") -> Mon | N39: All grades | P39: Saudi Arabia, Egypt, Jordan, Other countries | Q39: Online | R39: Free | S39: https://iacademy.classera.com/lectures-list/?course_title=27-26%20يوم%20الادخار%20العالمي&course_type=1&c=eyJjb3Vyc2VfaWQiOiIxMjc4MzMifQ | T39: =IF(TRIM(S39)="","Missing","Published") -> Published | U39: Registration Open | V39: Not started | Z39: =IF(N(X39)>0,N(Y39)/X39,"") | AE39: =IF(G39="","",IF(H39<TODAY(),"Past",IF(G39<=TODAY(),"In progress",IF(G39-TODAY()<=14,"Next 14 days",IF(G39-TODAY()<=45,"Next 45 days","Later"))))) -> Next 45 days | AF39: =IF(G39="","",IF(H39<TODAY(),"",G39-TODAY())) -> 25 | AG39: =IF(AND(AE39="Past",U39<>"Delivered",U39<>"Cancelled",U39<>"Postponed"),"Update status",IF(AND(T39="Missing",OR(AE39="In progress",AE39="Next 14 days")),"Add link",IF(AND(AE39="Next 14 days",V39<>"Published"),"Announce","")))
A40: ENR-07 | B40: Enrichment Academy | C40: Skill Courses | D40: Programming Fundamentals | E40: أساسيات البرمجة | F40: Enrichment Academy | G40: 46328 | H40: 46328 | I40: Confirmed | J40: =IF(G40="","",DATE(YEAR(G40),MONTH(G40),1)) -> 46327 | K40: =IF(G40="","",IF(G40<DATE(2027,2,1),"Semester 1","Semester 2")) -> Semester 1 | L40: =IF(I40="Confirmed",TEXT(G40,"ddd"),"TBC") -> Mon | N40: Elementary & Middle | P40: Saudi Arabia, Egypt, Jordan, Other countries | Q40: Online | R40: Free | S40: https://iacademy.classera.com/lectures-list/?course_title=اساسيات%20البرمجة%2026-27&course_type=1&c=eyJjb3Vyc2VfaWQiOiIxMjc4MzQifQ | T40: =IF(TRIM(S40)="","Missing","Published") -> Published | U40: Registration Open | V40: Not started | Z40: =IF(N(X40)>0,N(Y40)/X40,"") | AE40: =IF(G40="","",IF(H40<TODAY(),"Past",IF(G40<=TODAY(),"In progress",IF(G40-TODAY()<=14,"Next 14 days",IF(G40-TODAY()<=45,"Next 45 days","Later"))))) -> Next 45 days | AF40: =IF(G40="","",IF(H40<TODAY(),"",G40-TODAY())) -> 32 | AG40: =IF(AND(AE40="Past",U40<>"Delivered",U40<>"Cancelled",U40<>"Postponed"),"Update status",IF(AND(T40="Missing",OR(AE40="In progress",AE40="Next 14 days")),"Add link",IF(AND(AE40="Next 14 days",V40<>"Published"),"Announce","")))
A41: ENR-08 | B41: Enrichment Academy | C41: Skill Courses | D41: Roblox Programming | E41: دورة مهارات برمجة الروبلوكس | F41: Enrichment Academy | G41: 46335 | H41: 46335 | I41: Confirmed | J41: =IF(G41="","",DATE(YEAR(G41),MONTH(G41),1)) -> 46327 | K41: =IF(G41="","",IF(G41<DATE(2027,2,1),"Semester 1","Semester 2")) -> Semester 1 | L41: =IF(I41="Confirmed",TEXT(G41,"ddd"),"TBC") -> Mon | N41: Middle | P41: Saudi Arabia, Egypt, Jordan, Other countries | Q41: Online | R41: Free | S41: https://iacademy.classera.com/lectures-list/?course_title=26-27دورة%20مهارات%20برمجة%20الروبلوكس&course_type=1&c=eyJjb3Vyc2VfaWQiOiIxMjc4MzUifQ | T41: =IF(TRIM(S41)="","Missing","Published") -> Published | U41: Registration Open | V41: Not started | Z41: =IF(N(X41)>0,N(Y41)/X41,"") | AE41: =IF(G41="","",IF(H41<TODAY(),"Past",IF(G41<=TODAY(),"In progress",IF(G41-TODAY()<=14,"Next 14 days",IF(G41-TODAY()<=45,"Next 45 days","Later"))))) -> Next 45 days | AF41: =IF(G41="","",IF(H41<TODAY(),"",G41-TODAY())) -> 39 | AG41: =IF(AND(AE41="Past",U41<>"Delivered",U41<>"Cancelled",U41<>"Postponed"),"Update status",IF(AND(T41="Missing",OR(AE41="In progress",AE41="Next 14 days")),"Add link",IF(AND(AE41="Next 14 days",V41<>"Published"),"Announce","")))
A42: ENR-09 | B42: Enrichment Academy | C42: Skill Courses | D42: Arduino Skills | E42: مهارات الأردوينو | F42: Enrichment Academy | G42: 46342 | H42: 46342 | I42: Confirmed | J42: =IF(G42="","",DATE(YEAR(G42),MONTH(G42),1)) -> 46327 | K42: =IF(G42="","",IF(G42<DATE(2027,2,1),"Semester 1","Semester 2")) -> Semester 1 | L42: =IF(I42="Confirmed",TEXT(G42,"ddd"),"TBC") -> Mon | N42: Middle & Secondary | P42: Saudi Arabia, Egypt, Jordan, Other countries | Q42: Online | R42: Paid (Secondary) | T42: =IF(TRIM(S42)="","Missing","Published") -> Missing | U42: Planned | V42: Not started | Z42: =IF(N(X42)>0,N(Y42)/X42,"") | AE42: =IF(G42="","",IF(H42<TODAY(),"Past",IF(G42<=TODAY(),"In progress",IF(G42-TODAY()<=14,"Next 14 days",IF(G42-TODAY()<=45,"Next 45 days","Later"))))) -> Later | AF42: =IF(G42="","",IF(H42<TODAY(),"",G42-TODAY())) -> 46 | AG42: =IF(AND(AE42="Past",U42<>"Delivered",U42<>"Cancelled",U42<>"Postponed"),"Update status",IF(AND(T42="Missing",OR(AE42="In progress",AE42="Next 14 days")),"Add link",IF(AND(AE42="Next 14 days",V42<>"Published"),"Announce","")))
A43: ENR-10 | B43: Enrichment Academy | C43: Skill Courses | D43: Internet of Things | E43: مهارات إنترنت الأشياء | F43: Enrichment Academy | G43: 46349 | H43: 46349 | I43: Confirmed | J43: =IF(G43="","",DATE(YEAR(G43),MONTH(G43),1)) -> 46327 | K43: =IF(G43="","",IF(G43<DATE(2027,2,1),"Semester 1","Semester 2")) -> Semester 1 | L43: =IF(I43="Confirmed",TEXT(G43,"ddd"),"TBC") -> Mon | N43: Middle & Secondary | P43: Saudi Arabia, Egypt, Jordan, Other countries | Q43: Online | R43: Paid (Secondary) | S43: https://iacademy.classera.com/lectures-list/?course_title=26-27%20مهارات%20انترنيت%20الاشياء&course_type=1&c=eyJjb3Vyc2VfaWQiOiIxMjc4MzYifQ | T43: =IF(TRIM(S43)="","Missing","Published") -> Published | U43: Registration Open | V43: Not started | Z43: =IF(N(X43)>0,N(Y43)/X43,"") | AE43: =IF(G43="","",IF(H43<TODAY(),"Past",IF(G43<=TODAY(),"In progress",IF(G43-TODAY()<=14,"Next 14 days",IF(G43-TODAY()<=45,"Next 45 days","Later"))))) -> Later | AF43: =IF(G43="","",IF(H43<TODAY(),"",G43-TODAY())) -> 53 | AG43: =IF(AND(AE43="Past",U43<>"Delivered",U43<>"Cancelled",U43<>"Postponed"),"Update status",IF(AND(T43="Missing",OR(AE43="In progress",AE43="Next 14 days")),"Add link",IF(AND(AE43="Next 14 days",V43<>"Published"),"Announce","")))
A44: ENR-11 | B44: Enrichment Academy | C44: National & Awareness | D44: Riyali Financial Literacy Program (Flagship) | E44: برنامج ريالي للوعي المالي | F44: Enrichment Academy | G44: 46356 | H44: 46356 | I44: Confirmed | J44: =IF(G44="","",DATE(YEAR(G44),MONTH(G44),1)) -> 46327 | K44: =IF(G44="","",IF(G44<DATE(2027,2,1),"Semester 1","Semester 2")) -> Semester 1 | L44: =IF(I44="Confirmed",TEXT(G44,"ddd"),"TBC") -> Mon | N44: All grades | P44: Saudi Arabia, Egypt, Jordan, Other countries | Q44: Online | R44: Sponsored | S44: https://iacademy.classera.com/lectures-list/?course_title=26-27%20البرنامج%20ريالي%20للوعي%20المالي&course_type=1&c=eyJjb3Vyc2VfaWQiOiIxMjc4MzcifQ | T44: =IF(TRIM(S44)="","Missing","Published") -> Published | U44: Registration Open | V44: Not started | Z44: =IF(N(X44)>0,N(Y44)/X44,"") | AE44: =IF(G44="","",IF(H44<TODAY(),"Past",IF(G44<=TODAY(),"In progress",IF(G44-TODAY()<=14,"Next 14 days",IF(G44-TODAY()<=45,"Next 45 days","Later"))))) -> Later | AF44: =IF(G44="","",IF(H44<TODAY(),"",G44-TODAY())) -> 60 | AG44: =IF(AND(AE44="Past",U44<>"Delivered",U44<>"Cancelled",U44<>"Postponed"),"Update status",IF(AND(T44="Missing",OR(AE44="In progress",AE44="Next 14 days")),"Add link",IF(AND(AE44="Next 14 days",V44<>"Published"),"Announce","")))
A45: ENR-12 | B45: Enrichment Academy | C45: Skill Courses | D45: Python Programming | E45: البرمجة بلغة بايثون | F45: Enrichment Academy | G45: 46363 | H45: 46363 | I45: Confirmed | J45: =IF(G45="","",DATE(YEAR(G45),MONTH(G45),1)) -> 46357 | K45: =IF(G45="","",IF(G45<DATE(2027,2,1),"Semester 1","Semester 2")) -> Semester 1 | L45: =IF(I45="Confirmed",TEXT(G45,"ddd"),"TBC") -> Mon | N45: Secondary | P45: Saudi Arabia, Egypt, Jordan, Other countries | Q45: Online | R45: Paid (Secondary) | S45: https://iacademy.classera.com/lectures-list/?course_title=البرمجة%20بلغة%20بايثون%20%2026-27&course_type=1&c=eyJjb3Vyc2VfaWQiOiIxMjc4MzgifQ | T45: =IF(TRIM(S45)="","Missing","Published") -> Published | U45: Registration Open | V45: Not started | Z45: =IF(N(X45)>0,N(Y45)/X45,"") | AE45: =IF(G45="","",IF(H45<TODAY(),"Past",IF(G45<=TODAY(),"In progress",IF(G45-TODAY()<=14,"Next 14 days",IF(G45-TODAY()<=45,"Next 45 days","Later"))))) -> Later | AF45: =IF(G45="","",IF(H45<TODAY(),"",G45-TODAY())) -> 67 | AG45: =IF(AND(AE45="Past",U45<>"Delivered",U45<>"Cancelled",U45<>"Postponed"),"Update status",IF(AND(T45="Missing",OR(AE45="In progress",AE45="Next 14 days")),"Add link",IF(AND(AE45="Next 14 days",V45<>"Published"),"Announce","")))
A46: ENR-13 | B46: Enrichment Academy | C46: Skill Courses | D46: Cybersecurity Skills | E46: مهارات برمجية: الأمان الإلكتروني | F46: Enrichment Academy | G46: 46370 | H46: 46370 | I46: Confirmed | J46: =IF(G46="","",DATE(YEAR(G46),MONTH(G46),1)) -> 46357 | K46: =IF(G46="","",IF(G46<DATE(2027,2,1),"Semester 1","Semester 2")) -> Semester 1 | L46: =IF(I46="Confirmed",TEXT(G46,"ddd"),"TBC") -> Mon | N46: Middle & Secondary | P46: Saudi Arabia, Egypt, Jordan, Other countries | Q46: Online | R46: Paid (Secondary) | S46: https://iacademy.classera.com/lectures-list/?course_title=مهارات%20برمجية%20-%20الأمان%20الالكتروني%2026-27&course_type=1&c=eyJjb3Vyc2VfaWQiOiIxMjc4MzkifQ | T46: =IF(TRIM(S46)="","Missing","Published") -> Published | U46: Registration Open | V46: Not started | Z46: =IF(N(X46)>0,N(Y46)/X46,"") | AE46: =IF(G46="","",IF(H46<TODAY(),"Past",IF(G46<=TODAY(),"In progress",IF(G46-TODAY()<=14,"Next 14 days",IF(G46-TODAY()<=45,"Next 45 days","Later"))))) -> Later | AF46: =IF(G46="","",IF(H46<TODAY(),"",G46-TODAY())) -> 74 | AG46: =IF(AND(AE46="Past",U46<>"Delivered",U46<>"Cancelled",U46<>"Postponed"),"Update status",IF(AND(T46="Missing",OR(AE46="In progress",AE46="Next 14 days")),"Add link",IF(AND(AE46="Next 14 days",V46<>"Published"),"Announce","")))
...

Sheet Lists
A1: Program | B1: Event Status | C1: Announcement Status | D1: Date Status | E1: Delivery Mode | F1: Pricing
A2: Professional Development | B2: Planned | C2: Not started | D2: Confirmed | E2: Online | F2: Free
A3: Accreditation | B3: Confirmed | C3: Drafted | D3: Day TBC | E3: In-person | F3: Paid (Secondary)
A4: Enrichment Academy | B4: Registration Open | C4: In review | D4: Month TBC | E4: Hybrid | F4: Sponsored
A5: Product Events | B5: Delivered | C5: Approved | F5: Paid
A6: In-Person Events | B6: Postponed | C6: Published
B7: Cancelled

Sheet Off-Periods
A1: From | B1: To | C1: Off-Period (EN) | D1: Off-Period (AR) | E1: Country | F1: Days
A2: 46288 | B2: 46291 | C2: KSA National Day | D2: اليوم الوطني السعودي | E2: Saudi Arabia | F2: =B2-A2+1 -> 4
A3: 46346 | B3: 46354 | C3: KSA Autumn Break | D3: إجازة الخريف | E3: Saudi Arabia | F3: =B3-A3+1 -> 9
A4: 46389 | B4: 46395 | C4: Egypt exam-prep buffer | D4: فترة الاستعداد للامتحانات | E4: Egypt | F4: =B4-A4+1 -> 7
A5: 46395 | B5: 46403 | C5: KSA Mid-year Break | D5: إجازة منتصف العام | E5: Saudi Arabia | F5: =B5-A5+1 -> 9
A6: 46396 | B6: 46408 | C6: Egypt Term-1 Exams | D6: امتحانات الفصل الأول | E6: Egypt | F6: =B6-A6+1 -> 13
A7: 46410 | B7: 46422 | C7: Egypt Mid-year Break | D7: إجازة منتصف العام | E7: Egypt | F7: =B7-A7+1 -> 13
A8: 46437 | B8: 46440 | C8: KSA Founding Day | D8: يوم التأسيس السعودي | E8: Saudi Arabia | F8: =B8-A8+1 -> 4
A9: 46444 | B9: 46459 | C9: KSA Eid al-Fitr Break | D9: إجازة عيد الفطر | E9: Saudi Arabia | F9: =B9-A9+1 -> 16
A10: 46514 | B10: 46529 | C10: KSA Eid al-Adha Break | D10: إجازة عيد الأضحى | E10: Saudi Arabia | F10: =B10-A10+1 -> 16
A11: 46529 | B11: 46534 | C11: Egypt End-of-Year Exams | D11: امتحانات نهاية العام | E11: Egypt | F11: =B11-A11+1 -> 6
A13: Source: plans.classera.com Full Calendar (KSA and Egypt school calendars). No sessions are scheduled inside these periods.
